2025-01-01 16:42:38,113 | INFO | test_challenge" выполнен успешно
2025-01-01 16:42:38,114 | WARNING | Неверный тип данных для объекта Runner
Traceback (most recent call last):
  File "C:\Users\Татьяна\PycharmProjects\Module_12\tests_12_4.py", line 27, in test_run
    num_2 = Runner(5)
            ^^^^^^^^^
  File "C:\Users\Татьяна\PycharmProjects\Module_12\rt_with_exception.py", line 6, in __init__
    raise TypeError(f'Имя может быть только строкой, передано {type(name).__name__}')
TypeError: Имя может быть только строкой, передано int
2025-01-01 16:42:38,115 | WARNING | Неверная скорость для Runner
Traceback (most recent call last):
  File "C:\Users\Татьяна\PycharmProjects\Module_12\tests_12_4.py", line 9, in test_walk
    num_1 = Runner('Vasya', speed=-5)
            ^^^^^^^^^^^^^^^^^^^^^^^^^
  File "C:\Users\Татьяна\PycharmProjects\Module_12\rt_with_exception.py", line 11, in __init__
    raise ValueError(f'Скорость не может быть отрицательной, сейчас {speed}')
ValueError: Скорость не может быть отрицательной, сейчас -5
